Workbook

Sheet REKAP DATA
A2: Kategori | B2: Unit | C2: Indikator | D2: Satuan | E2: Unit Ter Target | F2: tgt_jan | G2: tgt_feb | H2: tgt_mar | I2: tgt_apr | J2: tgt_may | K2: tgt_jun | L2: tgt_jul | M2: tgt_aug | N2: tgt_sep | O2: tgt_oct | P2: tgt_nov | Q2: tgt_dec | R2: rls_jan | S2: rls_feb | T2: rls_mar | U2: rls_apr | V2: rls_may | W2: rls_jun | X2: rls_jul | Y2: rls_aug | Z2: rls_sep | AA2: rls_oct | AB2: rls_nov | AC2: rls_dec | AD2: tgt_mtd_jan | AE2: tgt_mtd_feb | AF2: tgt_mtd_mar | AG2: tgt_mtd_apr | AH2: tgt_mtd_may | AI2: tgt_mtd_jun | AJ2: tgt_mtd_jul | AK2: tgt_mtd_aug | AL2: tgt_mtd_sep | AM2: tgt_mtd_oct | AN2: tgt_mtd_nov | AO2: tgt_mtd_dec | AP2: rls_mtd_jan | AQ2: rls_mtd_feb | AR2: rls_mtd_mar | AS2: rls_mtd_apr | AT2: rls_mtd_may | AU2: rls_mtd_jun | AV2: rls_mtd_jul | AW2: rls_mtd_aug | AX2: rls_mtd_sep | AY2: rls_mtd_oct | AZ2: rls_mtd_nov | BA2: rls_mtd_dec | BB2: ach_jan | BC2: ach_feb | BD2: ach_mar | BE2: ach_apr | BF2: ach_may | BG2: ach_jun | BH2: ach_jul | BI2: ach_aug | BJ2: ach_sep | BK2: ach_oct | BL2: ach_nov | BM2: ach_dec
A3: RKAP | B3: EGBIS | C3: Revenue EGBIS | D3: Rp M | E3: TR5 | F3: =SUM(F4:F8) -> 7.0616074e+10 | G3: =SUM(G4:G8) -> 1.4692923e+11 | H3: =SUM(H4:H8) -> 2.0577951e+11 | I3: =SUM(I4:I8) -> 2.8109982e+11 | J3: =SUM(J4:J8) -> 3.5411981e+11 | K3: =SUM(K4:K8) -> 4.3117812e+11 | L3: =SUM(L4:L8) -> 5.1263803e+11 | M3: =SUM(M4:M8) -> 5.9547743e+11 | ... BA3: =SUM(BA4:BA8) -> 0 | BB3: =IF(F3=0,1,(R3/F3)) -> 1.1015362 | BC3: =IF(G3=0,1,(S3/G3)) -> 1.0721626 | BD3: =IF(H3=0,1,(T3/H3)) -> 1.021297 | BE3: =IF(I3=0,1,(U3/I3)) -> 1.0107469 | BF3: =IF(J3=0,1,(V3/J3)) -> 1.0063761 | BG3: =IF(K3=0,1,(W3/K3)) -> 0.82652082 | BH3: =IF(L3=0,1,(X3/L3)) -> 0.69518389 | BI3: =IF(M3=0,1,(Y3/M3)) -> 0.5984739 | ... BM3: =IF(Q3=0,1,(AC3/Q3)) -> 0.40467729
A4: RKAP | B4: EGBIS | C4: Revenue EGBIS | D4: Rp M | E4: PAPUA | F4: =AD4 -> 5.575481e+09 | G4: =F4+AE4 -> 1.1671894e+10 | H4: =G4+AF4 -> 1.6276061e+10 | I4: =H4+AG4 -> 2.2165441e+10 | J4: =I4+AH4 -> 2.7840408e+10 | K4: =J4+AI4 -> 3.4257764e+10 | L4: =K4+AJ4 -> 4.0594335e+10 | M4: =L4+AK4 -> 4.710561e+10 | N4: =M4+AL4 -> 5.197083e+10 | ... Q4: =P4+AO4 -> 6.8061054e+10 | R4: =AP4 -> 7526688385 | S4: =R4+AQ4 -> 13264985466 | T4: =S4+AR4 -> 16618308216 | U4: =T4+AS4 -> 21838565062 | V4: =U4+AT4 -> 26852222177 | W4: =V4+AU4 -> 26852222177 | X4: =W4+AV4 -> 26852222177 | Y4: =X4+AW4 -> 26852222177 | Z4: =Y4+AX4 -> 26852222177 | ... AC4: =AB4+BA4 -> 26852222177 | AD4: =AD40+AD154+AD232+AD304 -> 5.575481e+09 | AE4: =AE40+AE154+AE232+AE304 -> 6.0964131e+09 | AF4: =AF40+AF154+AF232+AF304 -> 4.6041669e+09 | AG4: =AG40+AG154+AG232+AG304 -> 5.8893796e+09 | AH4: =AH40+AH154+AH232+AH304 -> 5.6749677e+09 | AI4: =AI40+AI154+AI232+AI304 -> 6.4173561e+09 | AJ4: =AJ40+AJ154+AJ232+AJ304 -> 6.3365702e+09 | AK4: =AK40+AK154+AK232+AK304 -> 6.511275e+09 | ... BA4: =BA40+BA154+BA232+BA304 -> 0 | BB4: =IF(F4=0,1,(R4/F4)) -> 1.3499622 | BC4: =IF(G4=0,1,(S4/G4)) -> 1.1364895 | BD4: =IF(H4=0,1,(T4/H4)) -> 1.0210276 | BE4: =IF(I4=0,1,(U4/I4)) -> 0.98525292 | BF4: =IF(J4=0,1,(V4/J4)) -> 0.96450533 | BG4: =IF(K4=0,1,(W4/K4)) -> 0.78382879 | BH4: =IF(L4=0,1,(X4/L4)) -> 0.66147709 | BI4: =IF(M4=0,1,(Y4/M4)) -> 0.57004298 | ... BM4: =IF(Q4=0,1,(AC4/Q4)) -> 0.39453139
A5: RKAP | B5: EGBIS | C5: Revenue EGBIS | D5: Rp M | E5: PAPUA BARAT | F5: =AD5 -> 5.8993552e+09 | G5: =F5+AE5 -> 1.2642344e+10 | H5: =G5+AF5 -> 1.7525918e+10 | I5: =H5+AG5 -> 2.395514e+10 | J5: =I5+AH5 -> 3.0030581e+10 | K5: =J5+AI5 -> 3.7059274e+10 | L5: =K5+AJ5 -> 4.4012916e+10 | M5: =L5+AK5 -> 5.1081221e+10 | N5: =M5+AL5 -> 5.6312904e+10 | ... Q5: =P5+AO5 -> 7.3429219e+10 | R5: =AP5 -> 6393244496 | S5: =R5+AQ5 -> 17034823296 | T5: =S5+AR5 -> 20920947528 | U5: =T5+AS5 -> 27634802767 | V5: =U5+AT5 -> 34000519090 | W5: =V5+AU5 -> 34000519090 | X5: =W5+AV5 -> 34000519090 | Y5: =X5+AW5 -> 34000519090 | Z5: =Y5+AX5 -> 34000519090 | ... AC5: =AB5+BA5 -> 34000519090 | AD5: =AD41+AD155+AD233+AD305 -> 5.8993552e+09 | AE5: =AE41+AE155+AE233+AE305 -> 6.7429885e+09 | AF5: =AF41+AF155+AF233+AF305 -> 4.8835739e+09 | AG5: =AG41+AG155+AG233+AG305 -> 6.4292229e+09 | AH5: =AH41+AH155+AH233+AH305 -> 6.0754405e+09 | AI5: =AI41+AI155+AI233+AI305 -> 7.0286927e+09 | AJ5: =AJ41+AJ155+AJ233+AJ305 -> 6.9536421e+09 | AK5: =AK41+AK155+AK233+AK305 -> 7.068305e+09 | ... BA5: =BA41+BA155+BA233+BA305 -> 0 | BB5: =IF(F5=0,1,(R5/F5)) -> 1.0837192 | BC5: =IF(G5=0,1,(S5/G5)) -> 1.3474419 | BD5: =IF(H5=0,1,(T5/H5)) -> 1.1937148 | BE5: =IF(I5=0,1,(U5/I5)) -> 1.1536064 | BF5: =IF(J5=0,1,(V5/J5)) -> 1.1321965 | BG5: =IF(K5=0,1,(W5/K5)) -> 0.91746318 | BH5: =IF(L5=0,1,(X5/L5)) -> 0.77251231 | BI5: =IF(M5=0,1,(Y5/M5)) -> 0.66561681 | ... BM5: =IF(Q5=0,1,(AC5/Q5)) -> 0.463038
A6: RKAP | B6: EGBIS | C6: Revenue EGBIS | D6: Rp M | E6: SULBAGSEL | F6: =AD6 -> 2.3368854e+10 | G6: =F6+AE6 -> 4.8263094e+10 | H6: =G6+AF6 -> 6.7816898e+10 | I6: =H6+AG6 -> 9.2275552e+10 | J6: =I6+AH6 -> 1.1613916e+11 | K6: =J6+AI6 -> 1.4197122e+11 | L6: =K6+AJ6 -> 1.6824627e+11 | M6: =L6+AK6 -> 1.9522884e+11 | N6: =M6+AL6 -> 2.1619165e+11 | ... Q6: =P6+AO6 -> 2.8628778e+11 | R6: =AP6 -> 25184839139 | S6: =R6+AQ6 -> 50437538410 | T6: =S6+AR6 -> 6.4586283e+10 | U6: =T6+AS6 -> 8.939449e+10 | V6: =U6+AT6 -> 1.1484134e+11 | W6: =V6+AU6 -> 1.1484134e+11 | X6: =W6+AV6 -> 1.1484134e+11 | Y6: =X6+AW6 -> 1.1484134e+11 | Z6: =Y6+AX6 -> 1.1484134e+11 | ... AC6: =AB6+BA6 -> 1.1484134e+11 | AD6: =AD42+AD156+AD234+AD306 -> 2.3368854e+10 | AE6: =AE42+AE156+AE234+AE306 -> 2.4894241e+10 | AF6: =AF42+AF156+AF234+AF306 -> 1.9553803e+10 | AG6: =AG42+AG156+AG234+AG306 -> 2.4458654e+10 | AH6: =AH42+AH156+AH234+AH306 -> 2.3863604e+10 | AI6: =AI42+AI156+AI234+AI306 -> 2.5832066e+10 | AJ6: =AJ42+AJ156+AJ234+AJ306 -> 2.6275053e+10 | AK6: =AK42+AK156+AK234+AK306 -> 2.6982568e+10 | ... BA6: =BA42+BA156+BA234+BA306 -> 0 | BB6: =IF(F6=0,1,(R6/F6)) -> 1.0777096 | BC6: =IF(G6=0,1,(S6/G6)) -> 1.045054 | BD6: =IF(H6=0,1,(T6/H6)) -> 0.95236269 | BE6: =IF(I6=0,1,(U6/I6)) -> 0.96877762 | BF6: =IF(J6=0,1,(V6/J6)) -> 0.98882536 | BG6: =IF(K6=0,1,(W6/K6)) -> 0.80890578 | BH6: =IF(L6=0,1,(X6/L6)) -> 0.68257881 | BI6: =IF(M6=0,1,(Y6/M6)) -> 0.58823963 | ... BM6: =IF(Q6=0,1,(AC6/Q6)) -> 0.40113952
A7: RKAP | B7: EGBIS | C7: Revenue EGBIS | D7: Rp M | E7: SULBAGTENG | F7: =AD7 -> 1.4704483e+10 | G7: =F7+AE7 -> 3.1078562e+10 | H7: =G7+AF7 -> 4.3927794e+10 | I7: =H7+AG7 -> 6.0095266e+10 | J7: =I7+AH7 -> 7.5614607e+10 | K7: =J7+AI7 -> 9.1760108e+10 | L7: =K7+AJ7 -> 1.0924037e+11 | M7: =L7+AK7 -> 1.2673998e+11 | N7: =M7+AL7 -> 1.4127595e+11 | ... Q7: =P7+AO7 -> 1.8958587e+11 | R7: =AP7 -> 15921026307 | S7: =R7+AQ7 -> 30948649018 | T7: =S7+AR7 -> 49480776995 | U7: =T7+AS7 -> 62135898914 | V7: =U7+AT7 -> 75632281196 | W7: =V7+AU7 -> 75632281196 | X7: =W7+AV7 -> 75632281196 | Y7: =X7+AW7 -> 75632281196 | Z7: =Y7+AX7 -> 75632281196 | ... AC7: =AB7+BA7 -> 75632281196 | AD7: =AD43+AD157+AD235+AD307 -> 1.4704483e+10 | AE7: =AE43+AE157+AE235+AE307 -> 1.6374078e+10 | AF7: =AF43+AF157+AF235+AF307 -> 1.2849233e+10 | AG7: =AG43+AG157+AG235+AG307 -> 1.6167471e+10 | AH7: =AH43+AH157+AH235+AH307 -> 1.5519342e+10 | AI7: =AI43+AI157+AI235+AI307 -> 1.6145501e+10 | AJ7: =AJ43+AJ157+AJ235+AJ307 -> 1.7480262e+10 | AK7: =AK43+AK157+AK235+AK307 -> 1.7499607e+10 | ... BA7: =BA43+BA157+BA235+BA307 -> 0 | BB7: =IF(F7=0,1,(R7/F7)) -> 1.0827328 | BC7: =IF(G7=0,1,(S7/G7)) -> 0.99581986 | BD7: =IF(H7=0,1,(T7/H7)) -> 1.1264116 | BE7: =IF(I7=0,1,(U7/I7)) -> 1.0339566 | BF7: =IF(J7=0,1,(V7/J7)) -> 1.0002337 | BG7: =IF(K7=0,1,(W7/K7)) -> 0.82423923 | BH7: =IF(L7=0,1,(X7/L7)) -> 0.69234735 | BI7: =IF(M7=0,1,(Y7/M7)) -> 0.59675158 | ... BM7: =IF(Q7=0,1,(AC7/Q7)) -> 0.39893417
A8: RKAP | B8: EGBIS | C8: Revenue EGBIS | D8: Rp M | E8: SUMALUT | F8: =AD8 -> 2.1067901e+10 | G8: =F8+AE8 -> 4.327334e+10 | H8: =G8+AF8 -> 6.0232838e+10 | I8: =H8+AG8 -> 8.2608416e+10 | J8: =I8+AH8 -> 1.0449506e+11 | K8: =J8+AI8 -> 1.2612975e+11 | L8: =K8+AJ8 -> 1.5054413e+11 | M8: =L8+AK8 -> 1.7532178e+11 | N8: =M8+AL8 -> 1.9475657e+11 | ... Q8: =P8+AO8 -> 2.6328272e+11 | R8: =AP8 -> 22760362155 | S8: =R8+AQ8 -> 45846028574 | T8: =S8+AR8 -> 5.8555688e+10 | U8: =T8+AS8 -> 8.3117014e+10 | V8: =U8+AT8 -> 1.0505133e+11 | W8: =V8+AU8 -> 1.0505133e+11 | X8: =W8+AV8 -> 1.0505133e+11 | Y8: =X8+AW8 -> 1.0505133e+11 | Z8: =Y8+AX8 -> 1.0505133e+11 | ... AC8: =AB8+BA8 -> 1.0505133e+11 | AD8: =AD44+AD158+AD236+AD308 -> 2.1067901e+10 | AE8: =AE44+AE158+AE236+AE308 -> 2.2205439e+10 | AF8: =AF44+AF158+AF236+AF308 -> 1.6959498e+10 | AG8: =AG44+AG158+AG236+AG308 -> 2.2375578e+10 | AH8: =AH44+AH158+AH236+AH308 -> 2.1886642e+10 | AI8: =AI44+AI158+AI236+AI308 -> 2.1634695e+10 | AJ8: =AJ44+AJ158+AJ236+AJ308 -> 2.4414378e+10 | AK8: =AK44+AK158+AK236+AK308 -> 2.4777648e+10 | ... BA8: =BA44+BA158+BA236+BA308 -> 0 | BB8: =IF(F8=0,1,(R8/F8)) -> 1.0803336 | BC8: =IF(G8=0,1,(S8/G8)) -> 1.059452 | BD8: =IF(H8=0,1,(T8/H8)) -> 0.97215554 | BE8: =IF(I8=0,1,(U8/I8)) -> 1.0061567 | BF8: =IF(J8=0,1,(V8/J8)) -> 1.0053234 | BG8: =IF(K8=0,1,(W8/K8)) -> 0.83288304 | BH8: =IF(L8=0,1,(X8/L8)) -> 0.69781088 | BI8: =IF(M8=0,1,(Y8/M8)) -> 0.59919157 | ... BM8: =IF(Q8=0,1,(AC8/Q8)) -> 0.3990058
A9: RKAP | B9: EGBIS | C9: Revenue NGTMA EGBIS | D9: Rp M | E9: TR5 | F9: =SUM(F10:F14) -> 4.9216576e+09 | G9: =SUM(G10:G14) -> 1.103309e+10 | H9: =SUM(H10:H14) -> 1.5339661e+10 | I9: =SUM(I10:I14) -> 1.882143e+10 | J9: =SUM(J10:J14) -> 2.4168259e+10 | K9: =SUM(K10:K14) -> 2.9412731e+10 | L9: =SUM(L10:L14) -> 3.4596239e+10 | M9: =SUM(M10:M14) -> 3.9554241e+10 | ... BA9: =SUM(BA10:BA14) -> 0 | BB9: =IF(F9=0,1,(R9/F9)) -> 3.4082812 | BC9: =IF(G9=0,1,(S9/G9)) -> 1.7451226 | BD9: =IF(H9=0,1,(T9/H9)) -> 1.6232743 | BE9: =IF(I9=0,1,(U9/I9)) -> 1.4493207 | BF9: =IF(J9=0,1,(V9/J9)) -> 1.2122055 | BG9: =IF(K9=0,1,(W9/K9)) -> 1.0682621 | BH9: =IF(L9=0,1,(X9/L9)) -> 0.90820585 | BI9: =IF(M9=0,1,(Y9/M9)) -> 0.79436506 | ... BM9: =IF(Q9=0,1,(AC9/Q9)) -> 0.51488771
A10: RKAP | B10: EGBIS | C10: Revenue NGTMA EGBIS | D10: Rp M | E10: PAPUA | F10: =AD10 -> 1.2579531e+09 | G10: =F10+AE10 -> 2.7620736e+09 | H10: =G10+AF10 -> 3.7352304e+09 | I10: =H10+AG10 -> 4.4873312e+09 | J10: =I10+AH10 -> 5.7754471e+09 | K10: =J10+AI10 -> 7.0344284e+09 | L10: =K10+AJ10 -> 8.3196671e+09 | M10: =L10+AK10 -> 9.5377836e+09 | N10: =M10+AL10 -> 1.0714774e+10 | ... Q10: =P10+AO10 -> 1.4749913e+10 | R10: =AP10 -> 65500000 | S10: =R10+AQ10 -> 131000000 | T10: =S10+AR10 -> 196500000 | U10: =T10+AS10 -> 262000000 | V10: =U10+AT10 -> 327500000 | W10: =V10+AU10 -> 393000000 | X10: =W10+AV10 -> 393000000 | Y10: =X10+AW10 -> 393000000 | Z10: =Y10+AX10 -> 393000000 | ... AC10: =AB10+BA10 -> 393000000 | AD10: =AD58+AD172+AD250+AD328 -> 1.2579531e+09 | AE10: =AE58+AE172+AE250+AE328 -> 1.5041205e+09 | AF10: =AF58+AF172+AF250+AF328 -> 9.7315674e+08 | AG10: =AG58+AG172+AG250+AG328 -> 7.5210085e+08 | AH10: =AH58+AH172+AH250+AH328 -> 1.2881159e+09 | AI10: =AI58+AI172+AI250+AI328 -> 1.2589812e+09 | AJ10: =AJ58+AJ172+AJ250+AJ328 -> 1.2852387e+09 | AK10: =AK58+AK172+AK250+AK328 -> 1.2181166e+09 | ... BA10: =BA58+BA172+BA250+BA328 -> 0 | BB10: =IF(F10=0,1,(R10/F10)) -> 0.052068712 | BC10: =IF(G10=0,1,(S10/G10)) -> 0.047428135 | BD10: =IF(H10=0,1,(T10/H10)) -> 0.052607197 | BE10: =IF(I10=0,1,(U10/I10)) -> 0.058386597 | BF10: =IF(J10=0,1,(V10/J10)) -> 0.056705566 | BG10: =IF(K10=0,1,(W10/K10)) -> 0.055868079 | BH10: =IF(L10=0,1,(X10/L10)) -> 0.047237467 | BI10: =IF(M10=0,1,(Y10/M10)) -> 0.041204541 | ... BM10: =IF(Q10=0,1,(AC10/Q10)) -> 0.026644225
A11: RKAP | B11: EGBIS | C11: Revenue NGTMA EGBIS | D11: Rp M | E11: PAPUA BARAT | F11: =AD11 -> 7.0163405e+08 | G11: =F11+AE11 -> 1.6506208e+09 | H11: =G11+AF11 -> 2.2852821e+09 | I11: =H11+AG11 -> 2.7487103e+09 | J11: =I11+AH11 -> 3.5274699e+09 | K11: =J11+AI11 -> 4.2793587e+09 | L11: =K11+AJ11 -> 4.9846599e+09 | M11: =L11+AK11 -> 5.6551511e+09 | N11: =M11+AL11 -> 6.3196359e+09 | ... Q11: =P11+AO11 -> 8.7077641e+09 | R11: =AP11 -> 88157413 | S11: =R11+AQ11 -> 359168813 | T11: =S11+AR11 -> 3636305613 | U11: =T11+AS11 -> 3771811313 | V11: =U11+AT11 -> 3771811313 | W11: =V11+AU11 -> 3771811313 | X11: =W11+AV11 -> 3771811313 | Y11: =X11+AW11 -> 3771811313 | Z11: =Y11+AX11 -> 3771811313 | ... AC11: =AB11+BA11 -> 3771811313 | AD11: =AD59+AD173+AD251+AD329 -> 7.0163405e+08 | AE11: =AE59+AE173+AE251+AE329 -> 9.4898679e+08 | AF11: =AF59+AF173+AF251+AF329 -> 6.3466129e+08 | AG11: =AG59+AG173+AG251+AG329 -> 4.6342815e+08 | AH11: =AH59+AH173+AH251+AH329 -> 7.7875966e+08 | AI11: =AI59+AI173+AI251+AI329 -> 7.5188873e+08 | AJ11: =AJ59+AJ173+AJ251+AJ329 -> 7.0530123e+08 | AK11: =AK59+AK173+AK251+AK329 -> 6.7049119e+08 | ... BA11: =BA59+BA173+BA251+BA329 -> 0 | BB11: =IF(F11=0,1,(R11/F11)) -> 0.12564586 | BC11: =IF(G11=0,1,(S11/G11)) -> 0.21759619 | BD11: =IF(H11=0,1,(T11/H11)) -> 1.5911846 | BE11: =IF(I11=0,1,(U11/I11)) -> 1.3722113 | BF11: =IF(J11=0,1,(V11/J11)) -> 1.0692682 | BG11: =IF(K11=0,1,(W11/K11)) -> 0.8813964 | BH11: =IF(L11=0,1,(X11/L11)) -> 0.75668379 | BI11: =IF(M11=0,1,(Y11/M11)) -> 0.66696915 | ... BM11: =IF(Q11=0,1,(AC11/Q11)) -> 0.43315497
A12: RKAP | B12: EGBIS | C12: Revenue NGTMA EGBIS | D12: Rp M | E12: SULBAGSEL | F12: =AD12 -> 6.8970274e+08 | G12: =F12+AE12 -> 1.5865001e+09 | H12: =G12+AF12 -> 2.3250324e+09 | I12: =H12+AG12 -> 2.9774056e+09 | J12: =I12+AH12 -> 3.8091113e+09 | K12: =J12+AI12 -> 4.634107e+09 | L12: =K12+AJ12 -> 5.416413e+09 | M12: =L12+AK12 -> 6.1773483e+09 | N12: =M12+AL12 -> 6.9405186e+09 | ... Q12: =P12+AO12 -> 9.4996785e+09 | R12: =AP12 -> 50980772 | S12: =R12+AQ12 -> 50980772 | T12: =S12+AR12 -> 386280068 | U12: =T12+AS12 -> 386280068 | V12: =U12+AT12 -> 386280068 | W12: =V12+AU12 -> 386280068 | X12: =W12+AV12 -> 386280068 | Y12: =X12+AW12 -> 386280068 | Z12: =Y12+AX12 -> 386280068 | ... AC12: =AB12+BA12 -> 386280068 | AD12: =AD60+AD174+AD252+AD330 -> 6.8970274e+08 | AE12: =AE60+AE174+AE252+AE330 -> 8.9679733e+08 | AF12: =AF60+AF174+AF252+AF330 -> 7.385323e+08 | AG12: =AG60+AG174+AG252+AG330 -> 6.5237326e+08 | AH12: =AH60+AH174+AH252+AH330 -> 8.3170561e+08 | AI12: =AI60+AI174+AI252+AI330 -> 8.2499574e+08 | AJ12: =AJ60+AJ174+AJ252+AJ330 -> 7.8230601e+08 | AK12: =AK60+AK174+AK252+AK330 -> 7.6093531e+08 | ... BA12: =BA60+BA174+BA252+BA330 -> 0 | BB12: =IF(F12=0,1,(R12/F12)) -> 0.073917021 | BC12: =IF(G12=0,1,(S12/G12)) -> 0.032134112 | BD12: =IF(H12=0,1,(T12/H12)) -> 0.16613965 | BE12: =IF(I12=0,1,(U12/I12)) -> 0.12973713 | BF12: =IF(J12=0,1,(V12/J12)) -> 0.1014095 | BG12: =IF(K12=0,1,(W12/K12)) -> 0.08335588 | BH12: =IF(L12=0,1,(X12/L12)) -> 0.071316583 | BI12: =IF(M12=0,1,(Y12/M12)) -> 0.062531696 | ... BM12: =IF(Q12=0,1,(AC12/Q12)) -> 0.040662436
A13: RKAP | B13: EGBIS | C13: Revenue NGTMA EGBIS | D13: Rp M | E13: SULBAGTENG | F13: =AD13 -> 1.024766e+09 | G13: =F13+AE13 -> 2.3180077e+09 | H13: =G13+AF13 -> 3.2166847e+09 | I13: =H13+AG13 -> 3.9283752e+09 | J13: =I13+AH13 -> 5.043167e+09 | K13: =J13+AI13 -> 6.1331497e+09 | L13: =K13+AJ13 -> 7.2005669e+09 | M13: =L13+AK13 -> 8.2191999e+09 | N13: =M13+AL13 -> 9.2201297e+09 | ... Q13: =P13+AO13 -> 1.2676224e+10 | R13: =AP13 -> 1051721798 | S13: =R13+AQ13 -> 2034214484 | T13: =S13+AR13 -> 2847787984 | U13: =T13+AS13 -> 3869718484 | V13: =U13+AT13 -> 4683291984 | W13: =V13+AU13 -> 5601865484 | X13: =W13+AV13 -> 5601865484 | Y13: =X13+AW13 -> 5601865484 | Z13: =Y13+AX13 -> 5601865484 | ... AC13: =AB13+BA13 -> 5601865484 | AD13: =AD61+AD175+AD253+AD331 -> 1.024766e+09 | AE13: =AE61+AE175+AE253+AE331 -> 1.2932417e+09 | AF13: =AF61+AF175+AF253+AF331 -> 8.9867702e+08 | AG13: =AG61+AG175+AG253+AG331 -> 7.116905e+08 | AH13: =AH61+AH175+AH253+AH331 -> 1.1147918e+09 | AI13: =AI61+AI175+AI253+AI331 -> 1.0899827e+09 | AJ13: =AJ61+AJ175+AJ253+AJ331 -> 1.0674172e+09 | AK13: =AK61+AK175+AK253+AK331 -> 1.018633e+09 | ... BA13: =BA61+BA175+BA253+BA331 -> 0 | BB13: =IF(F13=0,1,(R13/F13)) -> 1.0263044 | BC13: =IF(G13=0,1,(S13/G13)) -> 0.87757022 | BD13: =IF(H13=0,1,(T13/H13)) -> 0.88531773 | BE13: =IF(I13=0,1,(U13/I13)) -> 0.98506846 | BF13: =IF(J13=0,1,(V13/J13)) -> 0.92864107 | BG13: =IF(K13=0,1,(W13/K13)) -> 0.91337498 | BH13: =IF(L13=0,1,(X13/L13)) -> 0.77797561 | BI13: =IF(M13=0,1,(Y13/M13)) -> 0.68155849 | ... BM13: =IF(Q13=0,1,(AC13/Q13)) -> 0.44191909
A14: RKAP | B14: EGBIS | C14: Revenue NGTMA EGBIS | D14: Rp M | E14: SUMALUT | F14: =AD14 -> 1.2476017e+09 | G14: =F14+AE14 -> 2.715888e+09 | H14: =G14+AF14 -> 3.7774317e+09 | I14: =H14+AG14 -> 4.6796081e+09 | J14: =I14+AH14 -> 6.0130642e+09 | K14: =J14+AI14 -> 7.3316878e+09 | L14: =K14+AJ14 -> 8.6749326e+09 | M14: =L14+AK14 -> 9.964758e+09 | N14: =M14+AL14 -> 1.1218453e+10 | ... Q14: =P14+AO14 -> 1.539042e+10 | R14: =AP14 -> 15518033251 | S14: =R14+AQ14 -> 16678731251 | T14: =S14+AR14 -> 17833604965 | U14: =T14+AS14 -> 18988478679 | V14: =U14+AT14 -> 20128014393 | W14: =V14+AU14 -> 21267550107 | X14: =W14+AV14 -> 21267550107 | Y14: =X14+AW14 -> 21267550107 | Z14: =Y14+AX14 -> 21267550107 | ... AC14: =AB14+BA14 -> 21267550107 | AD14: =AD62+AD176+AD254+AD332 -> 1.2476017e+09 | AE14: =AE62+AE176+AE254+AE332 -> 1.4682863e+09 | AF14: =AF62+AF176+AF254+AF332 -> 1.0615438e+09 | AG14: =AG62+AG176+AG254+AG332 -> 9.0217635e+08 | AH14: =AH62+AH176+AH254+AH332 -> 1.3334561e+09 | AI14: =AI62+AI176+AI254+AI332 -> 1.3186236e+09 | AJ14: =AJ62+AJ176+AJ254+AJ332 -> 1.3432448e+09 | AK14: =AK62+AK176+AK254+AK332 -> 1.2898254e+09 | ... BA14: =BA62+BA176+BA254+BA332 -> 0 | BB14: =IF(F14=0,1,(R14/F14)) -> 12.438292 | BC14: =IF(G14=0,1,(S14/G14)) -> 6.1411705 | BD14: =IF(H14=0,1,(T14/H14)) -> 4.7210926 | BE14: =IF(I14=0,1,(U14/I14)) -> 4.057707 | BF14: =IF(J14=0,1,(V14/J14)) -> 3.3473806 | BG14: =IF(K14=0,1,(W14/K14)) -> 2.9007714 | BH14: =IF(L14=0,1,(X14/L14)) -> 2.4516099 | BI14: =IF(M14=0,1,(Y14/M14)) -> 2.1342766 | ... BM14: =IF(Q14=0,1,(AC14/Q14)) -> 1.3818694
A15: RKAP | B15: EGBIS | C15: Sales Wireline EGBIS | D15: SST | E15: TR5 | F15: =SUM(F16:F20) -> 37 | G15: =SUM(G16:G20) -> 78 | H15: =SUM(H16:H20) -> 116 | I15: =SUM(I16:I20) -> 160 | J15: =SUM(J16:J20) -> 201 | K15: =SUM(K16:K20) -> 249 | L15: =SUM(L16:L20) -> 305 | M15: =SUM(M16:M20) -> 352 | ... BA15: =SUM(BA16:BA20) -> 0 | BB15: =IF(F15=0,1,(R15/F15)) -> 0.43243243 | BC15: =IF(G15=0,1,(S15/G15)) -> 0.35897436 | BD15: =IF(H15=0,1,(T15/H15)) -> 0.32758621 | BE15: =IF(I15=0,1,(U15/I15)) -> 0.2375 | BF15: =IF(J15=0,1,(V15/J15)) -> 0.18905473 | BG15: =IF(K15=0,1,(W15/K15)) -> 0.15261044 | BH15: =IF(L15=0,1,(X15/L15)) -> 0.12459016 | BI15: =IF(M15=0,1,(Y15/M15)) -> 0.10795455 | ... BM15: =IF(Q15=0,1,(AC15/Q15)) -> 0.06959707
A16: RKAP | B16: EGBIS | C16: Sales Wireline EGBIS | D16: SST | E16: PAPUA | F16: =AD16 -> 4 | G16: =F16+AE16 -> 7 | H16: =G16+AF16 -> 10 | I16: =H16+AG16 -> 14 | J16: =I16+AH16 -> 18 | K16: =J16+AI16 -> 23 | L16: =K16+AJ16 -> 28 | M16: =L16+AK16 -> 32 | N16: =M16+AL16 -> 36 | ... Q16: =P16+AO16 -> 49 | R16: =AP16 -> 0 | S16: =R16+AQ16 -> 1 | T16: =S16+AR16 -> 1 | U16: =T16+AS16 -> 1 | V16: =U16+AT16 -> 1 | W16: =V16+AU16 -> 1 | X16: =W16+AV16 -> 1 | Y16: =X16+AW16 -> 1 | Z16: =Y16+AX16 -> 1 | ... AC16: =AB16+BA16 -> 1 | AD16: =AD70+AD184+AD262+AD340 -> 4 | AE16: =AE70+AE184+AE262+AE340 -> 3 | AF16: =AF70+AF184+AF262+AF340 -> 3 | AG16: =AG70+AG184+AG262+AG340 -> 4 | AH16: =AH70+AH184+AH262+AH340 -> 4 | AI16: =AI70+AI184+AI262+AI340 -> 5 | AJ16: =AJ70+AJ184+AJ262+AJ340 -> 5 | AK16: =AK70+AK184+AK262+AK340 -> 4 | ... BA16: =BA70+BA184+BA262+BA340 -> 0 | BB16: =IF(F16=0,1,(R16/F16)) -> 0 | BC16: =IF(G16=0,1,(S16/G16)) -> 0.14285714 | BD16: =IF(H16=0,1,(T16/H16)) -> 0.1 | BE16: =IF(I16=0,1,(U16/I16)) -> 0.071428571 | BF16: =IF(J16=0,1,(V16/J16)) -> 0.055555556 | BG16: =IF(K16=0,1,(W16/K16)) -> 0.043478261 | BH16: =IF(L16=0,1,(X16/L16)) -> 0.035714286 | BI16: =IF(M16=0,1,(Y16/M16)) -> 0.03125 | ... BM16: =IF(Q16=0,1,(AC16/Q16)) -> 0.020408163
A17: RKAP | B17: EGBIS | C17: Sales Wireline EGBIS | D17: SST | E17: PAPUA BARAT | F17: =AD17 -> 3 | G17: =F17+AE17 -> 6 | H17: =G17+AF17 -> 9 | I17: =H17+AG17 -> 12 | J17: =I17+AH17 -> 15 | K17: =J17+AI17 -> 19 | L17: =K17+AJ17 -> 24 | M17: =L17+AK17 -> 28 | N17: =M17+AL17 -> 32 | ... Q17: =P17+AO17 -> 44 | R17: =AP17 -> 3 | S17: =R17+AQ17 -> 4 | T17: =S17+AR17 -> 4 | U17: =T17+AS17 -> 4 | V17: =U17+AT17 -> 4 | W17: =V17+AU17 -> 4 | X17: =W17+AV17 -> 4 | Y17: =X17+AW17 -> 4 | Z17: =Y17+AX17 -> 4 | ... AC17: =AB17+BA17 -> 4 | AD17: =AD71+AD185+AD263+AD341 -> 3 | AE17: =AE71+AE185+AE263+AE341 -> 3 | AF17: =AF71+AF185+AF263+AF341 -> 3 | AG17: =AG71+AG185+AG263+AG341 -> 3 | AH17: =AH71+AH185+AH263+AH341 -> 3 | AI17: =AI71+AI185+AI263+AI341 -> 4 | AJ17: =AJ71+AJ185+AJ263+AJ341 -> 5 | AK17: =AK71+AK185+AK263+AK341 -> 4 | ... BA17: =BA71+BA185+BA263+BA341 -> 0 | BB17: =IF(F17=0,1,(R17/F17)) -> 1 | BC17: =IF(G17=0,1,(S17/G17)) -> 0.66666667 | BD17: =IF(H17=0,1,(T17/H17)) -> 0.44444444 | BE17: =IF(I17=0,1,(U17/I17)) -> 0.33333333 | BF17: =IF(J17=0,1,(V17/J17)) -> 0.26666667 | BG17: =IF(K17=0,1,(W17/K17)) -> 0.21052632 | BH17: =IF(L17=0,1,(X17/L17)) -> 0.16666667 | BI17: =IF(M17=0,1,(Y17/M17)) -> 0.14285714 | ... BM17: =IF(Q17=0,1,(AC17/Q17)) -> 0.090909091
A18: RKAP | B18: EGBIS | C18: Sales Wireline EGBIS | D18: SST | E18: SULBAGSEL | F18: =AD18 -> 14 | G18: =F18+AE18 -> 30 | H18: =G18+AF18 -> 45 | I18: =H18+AG18 -> 62 | J18: =I18+AH18 -> 77 | K18: =J18+AI18 -> 96 | L18: =K18+AJ18 -> 116 | M18: =L18+AK18 -> 134 | N18: =M18+AL18 -> 150 | ... Q18: =P18+AO18 -> 204 | R18: =AP18 -> 5 | S18: =R18+AQ18 -> 9 | T18: =S18+AR18 -> 13 | U18: =T18+AS18 -> 13 | V18: =U18+AT18 -> 13 | W18: =V18+AU18 -> 13 | X18: =W18+AV18 -> 13 | Y18: =X18+AW18 -> 13 | Z18: =Y18+AX18 -> 13 | ... AC18: =AB18+BA18 -> 13 | AD18: =AD72+AD186+AD264+AD342 -> 14 | AE18: =AE72+AE186+AE264+AE342 -> 16 | AF18: =AF72+AF186+AF264+AF342 -> 15 | AG18: =AG72+AG186+AG264+AG342 -> 17 | AH18: =AH72+AH186+AH264+AH342 -> 15 | AI18: =AI72+AI186+AI264+AI342 -> 19 | AJ18: =AJ72+AJ186+AJ264+AJ342 -> 20 | AK18: =AK72+AK186+AK264+AK342 -> 18 | ... BA18: =BA72+BA186+BA264+BA342 -> 0 | BB18: =IF(F18=0,1,(R18/F18)) -> 0.35714286 | BC18: =IF(G18=0,1,(S18/G18)) -> 0.3 | BD18: =IF(H18=0,1,(T18/H18)) -> 0.28888889 | BE18: =IF(I18=0,1,(U18/I18)) -> 0.20967742 | BF18: =IF(J18=0,1,(V18/J18)) -> 0.16883117 | BG18: =IF(K18=0,1,(W18/K18)) -> 0.13541667 | BH18: =IF(L18=0,1,(X18/L18)) -> 0.11206897 | BI18: =IF(M18=0,1,(Y18/M18)) -> 0.097014925 | ... BM18: =IF(Q18=0,1,(AC18/Q18)) -> 0.06372549
A19: RKAP | B19: EGBIS | C19: Sales Wireline EGBIS | D19: SST | E19: SULBAGTENG | F19: =AD19 -> 8 | G19: =F19+AE19 -> 17 | H19: =G19+AF19 -> 25 | I19: =H19+AG19 -> 34 | J19: =I19+AH19 -> 42 | K19: =J19+AI19 -> 51 | L19: =K19+AJ19 -> 63 | M19: =L19+AK19 -> 72 | N19: =M19+AL19 -> 82 | ... Q19: =P19+AO19 -> 113 | R19: =AP19 -> 0 | S19: =R19+AQ19 -> 2 | T19: =S19+AR19 -> 4 | U19: =T19+AS19 -> 4 | V19: =U19+AT19 -> 4 | W19: =V19+AU19 -> 4 | X19: =W19+AV19 -> 4 | Y19: =X19+AW19 -> 4 | Z19: =Y19+AX19 -> 4 | ... AC19: =AB19+BA19 -> 4 | AD19: =AD73+AD187+AD265+AD343 -> 8 | AE19: =AE73+AE187+AE265+AE343 -> 9 | AF19: =AF73+AF187+AF265+AF343 -> 8 | AG19: =AG73+AG187+AG265+AG343 -> 9 | AH19: =AH73+AH187+AH265+AH343 -> 8 | AI19: =AI73+AI187+AI265+AI343 -> 9 | AJ19: =AJ73+AJ187+AJ265+AJ343 -> 12 | AK19: =AK73+AK187+AK265+AK343 -> 9 | ... BA19: =BA73+BA187+BA265+BA343 -> 0 | BB19: =IF(F19=0,1,(R19/F19)) -> 0 | BC19: =IF(G19=0,1,(S19/G19)) -> 0.11764706 | BD19: =IF(H19=0,1,(T19/H19)) -> 0.16 | BE19: =IF(I19=0,1,(U19/I19)) -> 0.11764706 | BF19: =IF(J19=0,1,(V19/J19)) -> 0.095238095 | BG19: =IF(K19=0,1,(W19/K19)) -> 0.078431373 | BH19: =IF(L19=0,1,(X19/L19)) -> 0.063492063 | BI19: =IF(M19=0,1,(Y19/M19)) -> 0.055555556 | ... BM19: =IF(Q19=0,1,(AC19/Q19)) -> 0.03539823
A20: RKAP | B20: EGBIS | C20: Sales Wireline EGBIS | D20: SST | E20: SUMALUT | F20: =AD20 -> 8 | G20: =F20+AE20 -> 18 | H20: =G20+AF20 -> 27 | I20: =H20+AG20 -> 38 | J20: =I20+AH20 -> 49 | K20: =J20+AI20 -> 60 | L20: =K20+AJ20 -> 74 | M20: =L20+AK20 -> 86 | N20: =M20+AL20 -> 99 | ... Q20: =P20+AO20 -> 136 | R20: =AP20 -> 8 | S20: =R20+AQ20 -> 12 | T20: =S20+AR20 -> 16 | U20: =T20+AS20 -> 16 | V20: =U20+AT20 -> 16 | W20: =V20+AU20 -> 16 | X20: =W20+AV20 -> 16 | Y20: =X20+AW20 -> 16 | Z20: =Y20+AX20 -> 16 | ... AC20: =AB20+BA20 -> 16 | AD20: =AD74+AD188+AD266+AD344 -> 8 | AE20: =AE74+AE188+AE266+AE344 -> 10 | AF20: =AF74+AF188+AF266+AF344 -> 9 | AG20: =AG74+AG188+AG266+AG344 -> 11 | AH20: =AH74+AH188+AH266+AH344 -> 11 | AI20: =AI74+AI188+AI266+AI344 -> 11 | AJ20: =AJ74+AJ188+AJ266+AJ344 -> 14 | AK20: =AK74+AK188+AK266+AK344 -> 12 | ... BA20: =BA74+BA188+BA266+BA344 -> 0 | BB20: =IF(F20=0,1,(R20/F20)) -> 1 | BC20: =IF(G20=0,1,(S20/G20)) -> 0.66666667 | BD20: =IF(H20=0,1,(T20/H20)) -> 0.59259259 | BE20: =IF(I20=0,1,(U20/I20)) -> 0.42105263 | BF20: =IF(J20=0,1,(V20/J20)) -> 0.32653061 | BG20: =IF(K20=0,1,(W20/K20)) -> 0.26666667 | BH20: =IF(L20=0,1,(X20/L20)) -> 0.21621622 | BI20: =IF(M20=0,1,(Y20/M20)) -> 0.18604651 | ... BM20: =IF(Q20=0,1,(AC20/Q20)) -> 0.11764706
A21: RKAP | B21: EGBIS | C21: Sales HSI EGBIS | D21: Rp M | E21: TR5 | F21: =SUM(F22:F26) -> 1338 | G21: =SUM(G22:G26) -> 2569 | H21: =SUM(H22:H26) -> 3765 | I21: =SUM(I22:I26) -> 5171 | J21: =SUM(J22:J26) -> 6445 | K21: =SUM(K22:K26) -> 7799 | L21: =SUM(L22:L26) -> 9378 | M21: =SUM(M22:M26) -> 10776 | ... BA21: =SUM(BA22:BA26) -> 0 | BB21: =IF(F21=0,1,(R21/F21)) -> 1.6584454 | BC21: =IF(G21=0,1,(S21/G21)) -> 1.5418451 | BD21: =IF(H21=0,1,(T21/H21)) -> 1.4169987 | BE21: =IF(I21=0,1,(U21/I21)) -> 1.380584 | BF21: =IF(J21=0,1,(V21/J21)) -> 1.3318852 | BG21: =IF(K21=0,1,(W21/K21)) -> 1.2868316 | BH21: =IF(L21=0,1,(X21/L21)) -> 1.0701642 | BI21: =IF(M21=0,1,(Y21/M21)) -> 0.93132888 | ... BM21: =IF(Q21=0,1,(AC21/Q21)) -> 0.60552673
A22: RKAP | B22: EGBIS | C22: Sales HSI EGBIS | D22: Rp M | E22: PAPUA | F22: =AD22 -> 119 | G22: =F22+AE22 -> 228 | H22: =G22+AF22 -> 335 | I22: =H22+AG22 -> 458 | J22: =I22+AH22 -> 570 | K22: =J22+AI22 -> 690 | L22: =K22+AJ22 -> 830 | M22: =L22+AK22 -> 954 | N22: =M22+AL22 -> 1086 | ... Q22: =P22+AO22 -> 1463 | R22: =AP22 -> 184 | S22: =R22+AQ22 -> 341 | T22: =S22+AR22 -> 471 | U22: =T22+AS22 -> 624 | V22: =U22+AT22 -> 762 | W22: =V22+AU22 -> 938 | X22: =W22+AV22 -> 938 | Y22: =X22+AW22 -> 938 | Z22: =Y22+AX22 -> 938 | ... AC22: =AB22+BA22 -> 938 | AD22: =AD82+AD190+AD268+AD346 -> 119 | AE22: =AE82+AE190+AE268+AE346 -> 109 | AF22: =AF82+AF190+AF268+AF346 -> 107 | AG22: =AG82+AG190+AG268+AG346 -> 123 | AH22: =AH82+AH190+AH268+AH346 -> 112 | AI22: =AI82+AI190+AI268+AI346 -> 120 | AJ22: =AJ82+AJ190+AJ268+AJ346 -> 140 | AK22: =AK82+AK190+AK268+AK346 -> 124 | ... BA22: =BA82+BA190+BA268+BA346 -> 0 | BB22: =IF(F22=0,1,(R22/F22)) -> 1.5462185 | BC22: =IF(G22=0,1,(S22/G22)) -> 1.495614 | BD22: =IF(H22=0,1,(T22/H22)) -> 1.4059701 | BE22: =IF(I22=0,1,(U22/I22)) -> 1.3624454 | BF22: =IF(J22=0,1,(V22/J22)) -> 1.3368421 | BG22: =IF(K22=0,1,(W22/K22)) -> 1.3594203 | BH22: =IF(L22=0,1,(X22/L22)) -> 1.1301205 | BI22: =IF(M22=0,1,(Y22/M22)) -> 0.98322851 | ... BM22: =IF(Q22=0,1,(AC22/Q22)) -> 0.64114833
A23: RKAP | B23: EGBIS | C23: Sales HSI EGBIS | D23: Rp M | E23: PAPUA BARAT | F23: =AD23 -> 108 | G23: =F23+AE23 -> 207 | H23: =G23+AF23 -> 306 | I23: =H23+AG23 -> 420 | J23: =I23+AH23 -> 523 | K23: =J23+AI23 -> 633 | L23: =K23+AJ23 -> 764 | M23: =L23+AK23 -> 880 | N23: =M23+AL23 -> 1002 | ... Q23: =P23+AO23 -> 1348 | R23: =AP23 -> 183 | S23: =R23+AQ23 -> 356 | T23: =S23+AR23 -> 513 | U23: =T23+AS23 -> 663 | V23: =U23+AT23 -> 828 | W23: =V23+AU23 -> 996 | X23: =W23+AV23 -> 996 | Y23: =X23+AW23 -> 996 | Z23: =Y23+AX23 -> 996 | ... AC23: =AB23+BA23 -> 996 | AD23: =AD83+AD191+AD269+AD347 -> 108 | AE23: =AE83+AE191+AE269+AE347 -> 99 | AF23: =AF83+AF191+AF269+AF347 -> 99 | AG23: =AG83+AG191+AG269+AG347 -> 114 | AH23: =AH83+AH191+AH269+AH347 -> 103 | AI23: =AI83+AI191+AI269+AI347 -> 110 | AJ23: =AJ83+AJ191+AJ269+AJ347 -> 131 | AK23: =AK83+AK191+AK269+AK347 -> 116 | ... BA23: =BA83+BA191+BA269+BA347 -> 0 | BB23: =IF(F23=0,1,(R23/F23)) -> 1.6944444 | BC23: =IF(G23=0,1,(S23/G23)) -> 1.7198068 | BD23: =IF(H23=0,1,(T23/H23)) -> 1.6764706 | BE23: =IF(I23=0,1,(U23/I23)) -> 1.5785714 | BF23: =IF(J23=0,1,(V23/J23)) -> 1.583174 | BG23: =IF(K23=0,1,(W23/K23)) -> 1.5734597 | BH23: =IF(L23=0,1,(X23/L23)) -> 1.3036649 | BI23: =IF(M23=0,1,(Y23/M23)) -> 1.1318182 | ... BM23: =IF(Q23=0,1,(AC23/Q23)) -> 0.7388724
A24: RKAP | B24: EGBIS | C24: Sales HSI EGBIS | D24: Rp M | E24: SULBAGSEL | F24: =AD24 -> 523 | G24: =F24+AE24 -> 1000 | H24: =G24+AF24 -> 1462 | I24: =H24+AG24 -> 2007 | J24: =I24+AH24 -> 2500 | K24: =J24+AI24 -> 3026 | L24: =K24+AJ24 -> 3637 | M24: =L24+AK24 -> 4176 | N24: =M24+AL24 -> 4758 | ... Q24: =P24+AO24 -> 6427 | R24: =AP24 -> 828 | S24: =R24+AQ24 -> 1510 | T24: =S24+AR24 -> 2040 | U24: =T24+AS24 -> 2753 | V24: =U24+AT24 -> 3311 | W24: =V24+AU24 -> 3813 | X24: =W24+AV24 -> 3813 | Y24: =X24+AW24 -> 3813 | Z24: =Y24+AX24 -> 3813 | ... AC24: =AB24+BA24 -> 3813 | AD24: =AD84+AD192+AD270+AD348 -> 523 | AE24: =AE84+AE192+AE270+AE348 -> 477 | AF24: =AF84+AF192+AF270+AF348 -> 462 | AG24: =AG84+AG192+AG270+AG348 -> 545 | AH24: =AH84+AH192+AH270+AH348 -> 493 | AI24: =AI84+AI192+AI270+AI348 -> 526 | AJ24: =AJ84+AJ192+AJ270+AJ348 -> 611 | AK24: =AK84+AK192+AK270+AK348 -> 539 | ... BA24: =BA84+BA192+BA270+BA348 -> 0 | BB24: =IF(F24=0,1,(R24/F24)) -> 1.583174 | BC24: =IF(G24=0,1,(S24/G24)) -> 1.51 | BD24: =IF(H24=0,1,(T24/H24)) -> 1.3953488 | BE24: =IF(I24=0,1,(U24/I24)) -> 1.3716991 | BF24: =IF(J24=0,1,(V24/J24)) -> 1.3244 | BG24: =IF(K24=0,1,(W24/K24)) -> 1.2600793 | BH24: =IF(L24=0,1,(X24/L24)) -> 1.0483915 | BI24: =IF(M24=0,1,(Y24/M24)) -> 0.91307471 | ... BM24: =IF(Q24=0,1,(AC24/Q24)) -> 0.59327836
A25: RKAP | B25: EGBIS | C25: Sales HSI EGBIS | D25: Rp M | E25: SULBAGTENG | F25: =AD25 -> 282 | G25: =F25+AE25 -> 541 | H25: =G25+AF25 -> 790 | I25: =H25+AG25 -> 1086 | J25: =I25+AH25 -> 1354 | K25: =J25+AI25 -> 1638 | L25: =K25+AJ25 -> 1968 | M25: =L25+AK25 -> 2260 | N25: =M25+AL25 -> 2573 | ... Q25: =P25+AO25 -> 3479 | R25: =AP25 -> 479 | S25: =R25+AQ25 -> 881 | T25: =S25+AR25 -> 1142 | U25: =T25+AS25 -> 1574 | V25: =U25+AT25 -> 1880 | W25: =V25+AU25 -> 2211 | X25: =W25+AV25 -> 2211 | Y25: =X25+AW25 -> 2211 | Z25: =Y25+AX25 -> 2211 | ... AC25: =AB25+BA25 -> 2211 | AD25: =AD85+AD193+AD271+AD349 -> 282 | AE25: =AE85+AE193+AE271+AE349 -> 259 | AF25: =AF85+AF193+AF271+AF349 -> 249 | AG25: =AG85+AG193+AG271+AG349 -> 296 | AH25: =AH85+AH193+AH271+AH349 -> 268 | AI25: =AI85+AI193+AI271+AI349 -> 284 | AJ25: =AJ85+AJ193+AJ271+AJ349 -> 330 | AK25: =AK85+AK193+AK271+AK349 -> 292 | ... BA25: =BA85+BA193+BA271+BA349 -> 0 | BB25: =IF(F25=0,1,(R25/F25)) -> 1.6985816 | BC25: =IF(G25=0,1,(S25/G25)) -> 1.6284658 | BD25: =IF(H25=0,1,(T25/H25)) -> 1.4455696 | BE25: =IF(I25=0,1,(U25/I25)) -> 1.4493554 | BF25: =IF(J25=0,1,(V25/J25)) -> 1.3884786 | BG25: =IF(K25=0,1,(W25/K25)) -> 1.3498168 | BH25: =IF(L25=0,1,(X25/L25)) -> 1.1234756 | BI25: =IF(M25=0,1,(Y25/M25)) -> 0.97831858 | ... BM25: =IF(Q25=0,1,(AC25/Q25)) -> 0.63552745
A26: RKAP | B26: EGBIS | C26: Sales HSI EGBIS | D26: Rp M | E26: SUMALUT | F26: =AD26 -> 306 | G26: =F26+AE26 -> 593 | H26: =G26+AF26 -> 872 | I26: =H26+AG26 -> 1200 | J26: =I26+AH26 -> 1498 | K26: =J26+AI26 -> 1812 | L26: =K26+AJ26 -> 2179 | M26: =L26+AK26 -> 2506 | N26: =M26+AL26 -> 2853 | ... Q26: =P26+AO26 -> 3857 | R26: =AP26 -> 545 | S26: =R26+AQ26 -> 873 | T26: =S26+AR26 -> 1169 | U26: =T26+AS26 -> 1525 | V26: =U26+AT26 -> 1803 | W26: =V26+AU26 -> 2078 | X26: =W26+AV26 -> 2078 | Y26: =X26+AW26 -> 2078 | Z26: =Y26+AX26 -> 2078 | ... AC26: =AB26+BA26 -> 2078 | AD26: =AD86+AD194+AD272+AD350 -> 306 | AE26: =AE86+AE194+AE272+AE350 -> 287 | AF26: =AF86+AF194+AF272+AF350 -> 279 | AG26: =AG86+AG194+AG272+AG350 -> 328 | AH26: =AH86+AH194+AH272+AH350 -> 298 | AI26: =AI86+AI194+AI272+AI350 -> 314 | AJ26: =AJ86+AJ194+AJ272+AJ350 -> 367 | AK26: =AK86+AK194+AK272+AK350 -> 327 | ... BA26: =BA86+BA194+BA272+BA350 -> 0 | BB26: =IF(F26=0,1,(R26/F26)) -> 1.7810458 | BC26: =IF(G26=0,1,(S26/G26)) -> 1.4721754 | BD26: =IF(H26=0,1,(T26/H26)) -> 1.3405963 | BE26: =IF(I26=0,1,(U26/I26)) -> 1.2708333 | BF26: =IF(J26=0,1,(V26/J26)) -> 1.2036048 | BG26: =IF(K26=0,1,(W26/K26)) -> 1.1467991 | BH26: =IF(L26=0,1,(X26/L26)) -> 0.95364846 | BI26: =IF(M26=0,1,(Y26/M26)) -> 0.8292099 | ... BM26: =IF(Q26=0,1,(AC26/Q26)) -> 0.53876069
A27: RKAP | B27: EGBIS | C27: Sales WMS EGBIS | D27: Rp M | E27: TR5 | F27: =SUM(F28:F32) -> 60 | G27: =SUM(G28:G32) -> 126 | H27: =SUM(H28:H32) -> 192 | I27: =SUM(I28:I32) -> 278 | J27: =SUM(J28:J32) -> 354 | K27: =SUM(K28:K32) -> 441 | L27: =SUM(L28:L32) -> 538 | M27: =SUM(M28:M32) -> 631 | ... BA27: =SUM(BA28:BA32) -> 0 | BB27: =IF(F27=0,1,(R27/F27)) -> 0.45 | BC27: =IF(G27=0,1,(S27/G27)) -> 0.53174603 | BD27: =IF(H27=0,1,(T27/H27)) -> 0.59895833 | BE27: =IF(I27=0,1,(U27/I27)) -> 0.70503597 | BF27: =IF(J27=0,1,(V27/J27)) -> 0.68361582 | BG27: =IF(K27=0,1,(W27/K27)) -> 0.61451247 | BH27: =IF(L27=0,1,(X27/L27)) -> 0.50371747 | BI27: =IF(M27=0,1,(Y27/M27)) -> 0.42947702 | ... BM27: =IF(Q27=0,1,(AC27/Q27)) -> 0.27208835
A28: RKAP | B28: EGBIS | C28: Sales WMS EGBIS | D28: Rp M | E28: PAPUA | F28: =AD28 -> 6 | G28: =F28+AE28 -> 12 | H28: =G28+AF28 -> 18 | I28: =H28+AG28 -> 26 | J28: =I28+AH28 -> 32 | K28: =J28+AI28 -> 41 | L28: =K28+AJ28 -> 50 | M28: =L28+AK28 -> 59 | N28: =M28+AL28 -> 69 | ... Q28: =P28+AO28 -> 94 | R28: =AP28 -> 3 | S28: =R28+AQ28 -> 8 | T28: =S28+AR28 -> 12 | U28: =T28+AS28 -> 25 | V28: =U28+AT28 -> 35 | W28: =V28+AU28 -> 38 | X28: =W28+AV28 -> 38 | Y28: =X28+AW28 -> 38 | Z28: =Y28+AX28 -> 38 | ... AC28: =AB28+BA28 -> 38 | AD28: =AD88+AD196+AD274+AD352 -> 6 | AE28: =AE88+AE196+AE274+AE352 -> 6 | AF28: =AF88+AF196+AF274+AF352 -> 6 | AG28: =AG88+AG196+AG274+AG352 -> 8 | AH28: =AH88+AH196+AH274+AH352 -> 6 | AI28: =AI88+AI196+AI274+AI352 -> 9 | AJ28: =AJ88+AJ196+AJ274+AJ352 -> 9 | AK28: =AK88+AK196+AK274+AK352 -> 9 | ... BA28: =BA88+BA196+BA274+BA352 -> 0 | BB28: =IF(F28=0,1,(R28/F28)) -> 0.5 | BC28: =IF(G28=0,1,(S28/G28)) -> 0.66666667 | BD28: =IF(H28=0,1,(T28/H28)) -> 0.66666667 | BE28: =IF(I28=0,1,(U28/I28)) -> 0.96153846 | BF28: =IF(J28=0,1,(V28/J28)) -> 1.09375 | BG28: =IF(K28=0,1,(W28/K28)) -> 0.92682927 | BH28: =IF(L28=0,1,(X28/L28)) -> 0.76 | BI28: =IF(M28=0,1,(Y28/M28)) -> 0.6440678 | ... BM28: =IF(Q28=0,1,(AC28/Q28)) -> 0.40425532
A29: RKAP | B29: EGBIS | C29: Sales WMS EGBIS | D29: Rp M | E29: PAPUA BARAT | F29: =AD29 -> 5 | G29: =F29+AE29 -> 11 | H29: =G29+AF29 -> 17 | I29: =H29+AG29 -> 26 | J29: =I29+AH29 -> 34 | K29: =J29+AI29 -> 42 | L29: =K29+AJ29 -> 52 | M29: =L29+AK29 -> 61 | N29: =M29+AL29 -> 70 | ... Q29: =P29+AO29 -> 93 | R29: =AP29 -> 0 | S29: =R29+AQ29 -> 1 | T29: =S29+AR29 -> 2 | U29: =T29+AS29 -> 10 | V29: =U29+AT29 -> 12 | W29: =V29+AU29 -> 12 | X29: =W29+AV29 -> 12 | Y29: =X29+AW29 -> 12 | Z29: =Y29+AX29 -> 12 | ... AC29: =AB29+BA29 -> 12 | AD29: =AD89+AD197+AD275+AD353 -> 5 | AE29: =AE89+AE197+AE275+AE353 -> 6 | AF29: =AF89+AF197+AF275+AF353 -> 6 | AG29: =AG89+AG197+AG275+AG353 -> 9 | AH29: =AH89+AH197+AH275+AH353 -> 8 | AI29: =AI89+AI197+AI275+AI353 -> 8 | AJ29: =AJ89+AJ197+AJ275+AJ353 -> 10 | AK29: =AK89+AK197+AK275+AK353 -> 9 | ... BA29: =BA89+BA197+BA275+BA353 -> 0 | BB29: =IF(F29=0,1,(R29/F29)) -> 0 | BC29: =IF(G29=0,1,(S29/G29)) -> 0.090909091 | BD29: =IF(H29=0,1,(T29/H29)) -> 0.11764706 | BE29: =IF(I29=0,1,(U29/I29)) -> 0.38461538 | BF29: =IF(J29=0,1,(V29/J29)) -> 0.35294118 | BG29: =IF(K29=0,1,(W29/K29)) -> 0.28571429 | BH29: =IF(L29=0,1,(X29/L29)) -> 0.23076923 | BI29: =IF(M29=0,1,(Y29/M29)) -> 0.19672131 | ... BM29: =IF(Q29=0,1,(AC29/Q29)) -> 0.12903226
A30: RKAP | B30: EGBIS | C30: Sales WMS EGBIS | D30: Rp M | E30: SULBAGSEL | F30: =AD30 -> 23 | G30: =F30+AE30 -> 47 | H30: =G30+AF30 -> 72 | I30: =H30+AG30 -> 102 | J30: =I30+AH30 -> 130 | K30: =J30+AI30 -> 163 | L30: =K30+AJ30 -> 198 | M30: =L30+AK30 -> 233 | N30: =M30+AL30 -> 272 | ... Q30: =P30+AO30 -> 373 | R30: =AP30 -> 9 | S30: =R30+AQ30 -> 21 | T30: =S30+AR30 -> 28 | U30: =T30+AS30 -> 57 | V30: =U30+AT30 -> 75 | W30: =V30+AU30 -> 86 | X30: =W30+AV30 -> 86 | Y30: =X30+AW30 -> 86 | Z30: =Y30+AX30 -> 86 | ... AC30: =AB30+BA30 -> 86 | AD30: =AD90+AD198+AD276+AD354 -> 23 | AE30: =AE90+AE198+AE276+AE354 -> 24 | AF30: =AF90+AF198+AF276+AF354 -> 25 | AG30: =AG90+AG198+AG276+AG354 -> 30 | AH30: =AH90+AH198+AH276+AH354 -> 28 | AI30: =AI90+AI198+AI276+AI354 -> 33 | AJ30: =AJ90+AJ198+AJ276+AJ354 -> 35 | AK30: =AK90+AK198+AK276+AK354 -> 35 | ... BA30: =BA90+BA198+BA276+BA354 -> 0 | BB30: =IF(F30=0,1,(R30/F30)) -> 0.39130435 | BC30: =IF(G30=0,1,(S30/G30)) -> 0.44680851 | BD30: =IF(H30=0,1,(T30/H30)) -> 0.38888889 | BE30: =IF(I30=0,1,(U30/I30)) -> 0.55882353 | BF30: =IF(J30=0,1,(V30/J30)) -> 0.57692308 | BG30: =IF(K30=0,1,(W30/K30)) -> 0.52760736 | BH30: =IF(L30=0,1,(X30/L30)) -> 0.43434343 | BI30: =IF(M30=0,1,(Y30/M30)) -> 0.36909871 | ... BM30: =IF(Q30=0,1,(AC30/Q30)) -> 0.230563
A31: RKAP | B31: EGBIS | C31: Sales WMS EGBIS | D31: Rp M | E31: SULBAGTENG | F31: =AD31 -> 12 | G31: =F31+AE31 -> 26 | H31: =G31+AF31 -> 39 | I31: =H31+AG31 -> 57 | J31: =I31+AH31 -> 73 | K31: =J31+AI31 -> 90 | L31: =K31+AJ31 -> 110 | M31: =L31+AK31 -> 128 | N31: =M31+AL31 -> 147 | ... Q31: =P31+AO31 -> 200 | R31: =AP31 -> 2 | S31: =R31+AQ31 -> 10 | T31: =S31+AR31 -> 39 | U31: =T31+AS31 -> 58 | V31: =U31+AT31 -> 66 | W31: =V31+AU31 -> 76 | X31: =W31+AV31 -> 76 | Y31: =X31+AW31 -> 76 | Z31: =Y31+AX31 -> 76 | ... AC31: =AB31+BA31 -> 76 | AD31: =AD91+AD199+AD277+AD355 -> 12 | AE31: =AE91+AE199+AE277+AE355 -> 14 | AF31: =AF91+AF199+AF277+AF355 -> 13 | AG31: =AG91+AG199+AG277+AG355 -> 18 | AH31: =AH91+AH199+AH277+AH355 -> 16 | AI31: =AI91+AI199+AI277+AI355 -> 17 | AJ31: =AJ91+AJ199+AJ277+AJ355 -> 20 | AK31: =AK91+AK199+AK277+AK355 -> 18 | ... BA31: =BA91+BA199+BA277+BA355 -> 0 | BB31: =IF(F31=0,1,(R31/F31)) -> 0.16666667 | BC31: =IF(G31=0,1,(S31/G31)) -> 0.38461538 | BD31: =IF(H31=0,1,(T31/H31)) -> 1 | BE31: =IF(I31=0,1,(U31/I31)) -> 1.0175439 | BF31: =IF(J31=0,1,(V31/J31)) -> 0.90410959 | BG31: =IF(K31=0,1,(W31/K31)) -> 0.84444444 | BH31: =IF(L31=0,1,(X31/L31)) -> 0.69090909 | BI31: =IF(M31=0,1,(Y31/M31)) -> 0.59375 | ... BM31: =IF(Q31=0,1,(AC31/Q31)) -> 0.38
A32: RKAP | B32: EGBIS | C32: Sales WMS EGBIS | D32: Rp M | E32: SUMALUT | F32: =AD32 -> 14 | G32: =F32+AE32 -> 30 | H32: =G32+AF32 -> 46 | I32: =H32+AG32 -> 67 | J32: =I32+AH32 -> 85 | K32: =J32+AI32 -> 105 | L32: =K32+AJ32 -> 128 | M32: =L32+AK32 -> 150 | N32: =M32+AL32 -> 174 | ... Q32: =P32+AO32 -> 236 | R32: =AP32 -> 13 | S32: =R32+AQ32 -> 27 | T32: =S32+AR32 -> 34 | U32: =T32+AS32 -> 46 | V32: =U32+AT32 -> 54 | W32: =V32+AU32 -> 59 | X32: =W32+AV32 -> 59 | Y32: =X32+AW32 -> 59 | Z32: =Y32+AX32 -> 59 | ... AC32: =AB32+BA32 -> 59 | AD32: =AD92+AD200+AD278+AD356 -> 14 | AE32: =AE92+AE200+AE278+AE356 -> 16 | AF32: =AF92+AF200+AF278+AF356 -> 16 | AG32: =AG92+AG200+AG278+AG356 -> 21 | AH32: =AH92+AH200+AH278+AH356 -> 18 | AI32: =AI92+AI200+AI278+AI356 -> 20 | AJ32: =AJ92+AJ200+AJ278+AJ356 -> 23 | AK32: =AK92+AK200+AK278+AK356 -> 22 | ... BA32: =BA92+BA200+BA278+BA356 -> 0 | BB32: =IF(F32=0,1,(R32/F32)) -> 0.92857143 | BC32: =IF(G32=0,1,(S32/G32)) -> 0.9 | BD32: =IF(H32=0,1,(T32/H32)) -> 0.73913043 | BE32: =IF(I32=0,1,(U32/I32)) -> 0.68656716 | BF32: =IF(J32=0,1,(V32/J32)) -> 0.63529412 | BG32: =IF(K32=0,1,(W32/K32)) -> 0.56190476 | BH32: =IF(L32=0,1,(X32/L32)) -> 0.4609375 | BI32: =IF(M32=0,1,(Y32/M32)) -> 0.39333333 | ... BM32: =IF(Q32=0,1,(AC32/Q32)) -> 0.25
A33: RKAP | B33: EGBIS | C33: Sales BW EGBIS | D33: Rp M | E33: TR5 | F33: =SUM(F34:F38) -> 3459 | G33: =SUM(G34:G38) -> 13922.008 | H33: =SUM(H34:H38) -> 23486.014 | I33: =SUM(I34:I38) -> 33109.022 | J33: =SUM(J34:J38) -> 41088.031 | K33: =SUM(K34:K38) -> 49349.037 | L33: =SUM(L34:L38) -> 58899.047 | M33: =SUM(M34:M38) -> 67330.056 | ... BA33: =SUM(BA34:BA38) -> 0 | BB33: =IF(F33=0,1,(R33/F33)) -> 1.6123238 | BC33: =IF(G33=0,1,(S33/G33)) -> 1.0485577 | BD33: =IF(H33=0,1,(T33/H33)) -> 0.9687948 | BE33: =IF(I33=0,1,(U33/I33)) -> 0.83380076 | BF33: =IF(J33=0,1,(V33/J33)) -> 0.99725948 | BG33: =IF(K33=0,1,(W33/K33)) -> 0.9042933 | BH33: =IF(L33=0,1,(X33/L33)) -> 0.75766938 | BI33: =IF(M33=0,1,(Y33/M33)) -> 0.66279469 | ... BM33: =IF(Q33=0,1,(AC33/Q33)) -> 0.43555372
A34: RKAP | B34: EGBIS | C34: Sales BW EGBIS | D34: Rp M | E34: PAPUA | F34: =AD34 -> 338.54032 | G34: =F34+AE34 -> 1274.6781 | H34: =G34+AF34 -> 2163.0809 | I34: =H34+AG34 -> 2991.5634 | J34: =I34+AH34 -> 3648.8724 | K34: =J34+AI34 -> 4365.3786 | L34: =K34+AJ34 -> 5159.3513 | M34: =L34+AK34 -> 5839.9567 | N34: =M34+AL34 -> 6497.9084 | ... Q34: =P34+AO34 -> 8714.5171 | R34: =AP34 -> 667.3 | S34: =R34+AQ34 -> 942.3 | T34: =S34+AR34 -> 1121.3 | U34: =T34+AS34 -> 1273.3 | V34: =U34+AT34 -> 3078.3 | W34: =V34+AU34 -> 3152.748 | X34: =W34+AV34 -> 3152.748 | Y34: =X34+AW34 -> 3152.748 | Z34: =Y34+AX34 -> 3152.748 | ... AC34: =AB34+BA34 -> 3152.748 | AD34: =AD94+AD202+AD280+AD358 -> 338.54032 | AE34: =AE94+AE202+AE280+AE358 -> 936.13781 | AF34: =AF94+AF202+AF280+AF358 -> 888.40274 | AG34: =AG94+AG202+AG280+AG358 -> 828.48257 | AH34: =AH94+AH202+AH280+AH358 -> 657.30891 | AI34: =AI94+AI202+AI280+AI358 -> 716.50621 | AJ34: =AJ94+AJ202+AJ280+AJ358 -> 793.97272 | AK34: =AK94+AK202+AK280+AK358 -> 680.6054 | ... BA34: =BA94+BA202+BA280+BA358 -> 0 | BB34: =IF(F34=0,1,(R34/F34)) -> 1.9711094 | BC34: =IF(G34=0,1,(S34/G34)) -> 0.73924544 | BD34: =IF(H34=0,1,(T34/H34)) -> 0.51838099 | BE34: =IF(I34=0,1,(U34/I34)) -> 0.42563028 | BF34: =IF(J34=0,1,(V34/J34)) -> 0.8436305 | BG34: =IF(K34=0,1,(W34/K34)) -> 0.7222164 | BH34: =IF(L34=0,1,(X34/L34)) -> 0.6110745 | BI34: =IF(M34=0,1,(Y34/M34)) -> 0.53985811 | ... BM34: =IF(Q34=0,1,(AC34/Q34)) -> 0.36178115
A35: RKAP | B35: EGBIS | C35: Sales BW EGBIS | D35: Rp M | E35: PAPUA BARAT | F35: =AD35 -> 348.47207 | G35: =F35+AE35 -> 1483.6343 | H35: =G35+AF35 -> 2542.0945 | I35: =H35+AG35 -> 3540.3989 | J35: =I35+AH35 -> 4327.8534 | K35: =J35+AI35 -> 5199.4641 | L35: =K35+AJ35 -> 6163.3246 | M35: =L35+AK35 -> 6989.7882 | N35: =M35+AL35 -> 7790.9818 | ... Q35: =P35+AO35 -> 10467.035 | R35: =AP35 -> 110.1 | S35: =R35+AQ35 -> 2766.1 | T35: =S35+AR35 -> 2906.1 | U35: =T35+AS35 -> 3191.1 | V35: =U35+AT35 -> 3515.1 | W35: =V35+AU35 -> 3668.1 | X35: =W35+AV35 -> 3668.1 | Y35: =X35+AW35 -> 3668.1 | Z35: =Y35+AX35 -> 3668.1 | ... AC35: =AB35+BA35 -> 3668.1 | AD35: =AD95+AD203+AD281+AD359 -> 348.47207 | AE35: =AE95+AE203+AE281+AE359 -> 1135.1623 | AF35: =AF95+AF203+AF281+AF359 -> 1058.4602 | AG35: =AG95+AG203+AG281+AG359 -> 998.30436 | AH35: =AH95+AH203+AH281+AH359 -> 787.45449 | AI35: =AI95+AI203+AI281+AI359 -> 871.61068 | AJ35: =AJ95+AJ203+AJ281+AJ359 -> 963.86049 | AK35: =AK95+AK203+AK281+AK359 -> 826.46359 | ... BA35: =BA95+BA203+BA281+BA359 -> 0 | BB35: =IF(F35=0,1,(R35/F35)) -> 0.31595072 | BC35: =IF(G35=0,1,(S35/G35)) -> 1.8644082 | BD35: =IF(H35=0,1,(T35/H35)) -> 1.1431912 | BE35: =IF(I35=0,1,(U35/I35)) -> 0.90133911 | BF35: =IF(J35=0,1,(V35/J35)) -> 0.81220404 | BG35: =IF(K35=0,1,(W35/K35)) -> 0.70547656 | BH35: =IF(L35=0,1,(X35/L35)) -> 0.59514958 | BI35: =IF(M35=0,1,(Y35/M35)) -> 0.52477985 | ... BM35: =IF(Q35=0,1,(AC35/Q35)) -> 0.35044307
A36: RKAP | B36: EGBIS | C36: Sales BW EGBIS | D36: Rp M | E36: SULBAGSEL | F36: =AD36 -> 1320.4407 | G36: =F36+AE36 -> 4712.0931 | H36: =G36+AF36 -> 7907.6069 | I36: =H36+AG36 -> 10984.972 | J36: =I36+AH36 -> 13488.375 | K36: =J36+AI36 -> 16134.91 | L36: =K36+AJ36 -> 19126.902 | M36: =L36+AK36 -> 21726.356 | N36: =M36+AL36 -> 24216.266 | ... Q36: =P36+AO36 -> 32666.417 | R36: =AP36 -> 3581.128 | S36: =R36+AQ36 -> 4321.128 | T36: =S36+AR36 -> 5971.628 | U36: =T36+AS36 -> 9423.628 | V36: =U36+AT36 -> 13337.728 | W36: =V36+AU36 -> 13940.728 | X36: =W36+AV36 -> 13940.728 | Y36: =X36+AW36 -> 13940.728 | Z36: =Y36+AX36 -> 13940.728 | ... AC36: =AB36+BA36 -> 13940.728 | AD36: =AD96+AD204+AD282+AD360 -> 1320.4407 | AE36: =AE96+AE204+AE282+AE360 -> 3391.6525 | AF36: =AF96+AF204+AF282+AF360 -> 3195.5138 | AG36: =AG96+AG204+AG282+AG360 -> 3077.3649 | AH36: =AH96+AH204+AH282+AH360 -> 2503.4032 | AI36: =AI96+AI204+AI282+AI360 -> 2646.5355 | AJ36: =AJ96+AJ204+AJ282+AJ360 -> 2991.9915 | AK36: =AK96+AK204+AK282+AK360 -> 2599.4538 | ... BA36: =BA96+BA204+BA282+BA360 -> 0 | BB36: =IF(F36=0,1,(R36/F36)) -> 2.7120704 | BC36: =IF(G36=0,1,(S36/G36)) -> 0.91702941 | BD36: =IF(H36=0,1,(T36/H36)) -> 0.75517512 | BE36: =IF(I36=0,1,(U36/I36)) -> 0.85786547 | BF36: =IF(J36=0,1,(V36/J36)) -> 0.98883135 | BG36: =IF(K36=0,1,(W36/K36)) -> 0.86401025 | BH36: =IF(L36=0,1,(X36/L36)) -> 0.72885447 | BI36: =IF(M36=0,1,(Y36/M36)) -> 0.64165054 | ... BM36: =IF(Q36=0,1,(AC36/Q36)) -> 0.42676024
A37: RKAP | B37: EGBIS | C37: Sales BW EGBIS | D37: Rp M | E37: SULBAGTENG | F37: =AD37 -> 657.96458 | G37: =F37+AE37 -> 2826.9333 | H37: =G37+AF37 -> 4738.7482 | I37: =H37+AG37 -> 6777.8142 | J37: =I37+AH37 -> 8491.5422 | K37: =J37+AI37 -> 10277.219 | L37: =K37+AJ37 -> 12356.638 | M37: =L37+AK37 -> 14205.788 | N37: =M37+AL37 -> 15969.85 | ... Q37: =P37+AO37 -> 21877.154 | R37: =AP37 -> 666.5 | S37: =R37+AQ37 -> 1056.5 | T37: =S37+AR37 -> 5914.1 | U37: =T37+AS37 -> 6134.1 | V37: =U37+AT37 -> 7879.1 | W37: =V37+AU37 -> 8051.228 | X37: =W37+AV37 -> 8051.228 | Y37: =X37+AW37 -> 8051.228 | Z37: =Y37+AX37 -> 8051.228 | ... AC37: =AB37+BA37 -> 8051.228 | AD37: =AD97+AD205+AD283+AD361 -> 657.96458 | AE37: =AE97+AE205+AE283+AE361 -> 2168.9687 | AF37: =AF97+AF205+AF283+AF361 -> 1911.8149 | AG37: =AG97+AG205+AG283+AG361 -> 2039.066 | AH37: =AH97+AH205+AH283+AH361 -> 1713.728 | AI37: =AI97+AI205+AI283+AI361 -> 1785.677 | AJ37: =AJ97+AJ205+AJ283+AJ361 -> 2079.4184 | AK37: =AK97+AK205+AK283+AK361 -> 1849.1501 | ... BA37: =BA97+BA205+BA283+BA361 -> 0 | BB37: =IF(F37=0,1,(R37/F37)) -> 1.0129725 | BC37: =IF(G37=0,1,(S37/G37)) -> 0.37372655 | BD37: =IF(H37=0,1,(T37/H37)) -> 1.24803 | BE37: =IF(I37=0,1,(U37/I37)) -> 0.90502628 | BF37: =IF(J37=0,1,(V37/J37)) -> 0.92787621 | BG37: =IF(K37=0,1,(W37/K37)) -> 0.7834053 | BH37: =IF(L37=0,1,(X37/L37)) -> 0.6515711 | BI37: =IF(M37=0,1,(Y37/M37)) -> 0.56675688 | ... BM37: =IF(Q37=0,1,(AC37/Q37)) -> 0.3680199
A38: RKAP | B38: EGBIS | C38: Sales BW EGBIS | D38: Rp M | E38: SUMALUT | F38: =AD38 -> 793.58238 | G38: =F38+AE38 -> 3624.6691 | H38: =G38+AF38 -> 6134.4833 | I38: =H38+AG38 -> 8814.274 | J38: =I38+AH38 -> 11131.388 | K38: =J38+AI38 -> 13372.065 | L38: =K38+AJ38 -> 16092.831 | M38: =L38+AK38 -> 18568.168 | N38: =M38+AL38 -> 20802.057 | ... Q38: =P38+AO38 -> 28732.969 | R38: =AP38 -> 552 | S38: =R38+AQ38 -> 5512 | T38: =S38+AR38 -> 6840 | U38: =T38+AS38 -> 7584.2 | V38: =U38+AT38 -> 13165.2 | W38: =V38+AU38 -> 15813.2 | X38: =W38+AV38 -> 15813.2 | Y38: =X38+AW38 -> 15813.2 | Z38: =Y38+AX38 -> 15813.2 | ... AC38: =AB38+BA38 -> 15813.2 | AD38: =AD98+AD206+AD284+AD362 -> 793.58238 | AE38: =AE98+AE206+AE284+AE362 -> 2831.0868 | AF38: =AF98+AF206+AF284+AF362 -> 2509.8142 | AG38: =AG98+AG206+AG284+AG362 -> 2679.7907 | AH38: =AH98+AH206+AH284+AH362 -> 2317.1137 | AI38: =AI98+AI206+AI284+AI362 -> 2240.6774 | AJ38: =AJ98+AJ206+AJ284+AJ362 -> 2720.7663 | AK38: =AK98+AK206+AK284+AK362 -> 2475.3364 | ... BA38: =BA98+BA206+BA284+BA362 -> 0 | BB38: =IF(F38=0,1,(R38/F38)) -> 0.69557996 | BC38: =IF(G38=0,1,(S38/G38)) -> 1.5206905 | BD38: =IF(H38=0,1,(T38/H38)) -> 1.1150083 | BE38: =IF(I38=0,1,(U38/I38)) -> 0.86044523 | BF38: =IF(J38=0,1,(V38/J38)) -> 1.1827097 | BG38: =IF(K38=0,1,(W38/K38)) -> 1.1825548 | BH38: =IF(L38=0,1,(X38/L38)) -> 0.98262386 | BI38: =IF(M38=0,1,(Y38/M38)) -> 0.85162953 | ... BM38: =IF(Q38=0,1,(AC38/Q38)) -> 0.55035036
A39: RKAP | B39: {=_xlfn.VSTACK(_xlfn._xlws.FILTER(RSMES!A3:D1000,RSMES!A3:A1000<>""),_xlfn._xlws.FILTER(RLEGS!A3:D1030,RLEGS!A3:A1030<>""),_xlfn._xlws.FILTER(RSO!A3:D1000,RSO!A3:A1000<>""),_xlfn._xlws.FILTER(BPPLP!A3:D1000,BPPLP!A3:A1000<>""),_xlfn._xlws.FILTER(SSGS!A3:D1000,SSGS!A3:A1000<>""))} -> SMES | C39: Revenue SMES | D39: Rp M | E39: TR5 | F39: {=SUM(IF(TARGET_TR5!$B$2:$B$2040=$A39,IF(TARGET_TR5!$C$2:$C$2040=$C39,IF(TARGET_TR5!$E$2:$E$2040=$E39,IF(TARGET_TR5!$W$1:$AH$1=F$2,TARGET_TR5!$W$2:$AH$2040)))))} -> 29765979369 | G39: {=SUM(IF(TARGET_TR5!$B$2:$B$2040=$A39,IF(TARGET_TR5!$C$2:$C$2040=$C39,IF(TARGET_TR5!$E$2:$E$2040=$E39,IF(TARGET_TR5!$W$1:$AH$1=G$2,TARGET_TR5!$W$2:$AH$2040)))))} -> 59877517312 | H39: {=SUM(IF(TARGET_TR5!$B$2:$B$2040=$A39,IF(TARGET_TR5!$C$2:$C$2040=$C39,IF(TARGET_TR5!$E$2:$E$2040=$E39,IF(TARGET_TR5!$W$1:$AH$1=H$2,TARGET_TR5!$W$2:$AH$2040)))))} -> 90154011580 | I39: {=SUM(IF(TARGET_TR5!$B$2:$B$2040=$A39,IF(TARGET_TR5!$C$2:$C$2040=$C39,IF(TARGET_TR5!$E$2:$E$2040=$E39,IF(TARGET_TR5!$W$1:$AH$1=I$2,TARGET_TR5!$W$2:$AH$2040)))))} -> 120878846529 | J39: {=SUM(IF(TARGET_TR5!$B$2:$B$2040=$A39,IF(TARGET_TR5!$C$2:$C$2040=$C39,IF(TARGET_TR5!$E$2:$E$2040=$E39,IF(TARGET_TR5!$W$1:$AH$1=J$2,TARGET_TR5!$W$2:$AH$2040)))))} -> 151934109769 | K39: {=SUM(IF(TARGET_TR5!$B$2:$B$2040=$A39,IF(TARGET_TR5!$C$2:$C$2040=$C39,IF(TARGET_TR5!$E$2:$E$2040=$E39,IF(TARGET_TR5!$W$1:$AH$1=K$2,TARGET_TR5!$W$2:$AH$2040)))))} -> 182990972869 | L39: {=SUM(IF(TARGET_TR5!$B$2:$B$2040=$A39,IF(TARGET_TR5!$C$2:$C$2040=$C39,IF(TARGET_TR5!$E$2:$E$2040=$E39,IF(TARGET_TR5!$W$1:$AH$1=L$2,TARGET_TR5!$W$2:$AH$2040)))))} -> 214793104956 | M39: {=SUM(IF(TARGET_TR5!$B$2:$B$2040=$A39,IF(TARGET_TR5!$C$2:$C$2040=$C39,IF(TARGET_TR5!$E$2:$E$2040=$E39,IF(TARGET_TR5!$W$1:$AH$1=M$2,TARGET_TR5!$W$2:$AH$2040)))))} -> 247074618081 | ... Q39: {=SUM(IF(TARGET_TR5!$B$2:$B$2040=$A39,IF(TARGET_TR5!$C$2:$C$2040=$C39,IF(TARGET_TR5!$E$2:$E$2040=$E39,IF(TARGET_TR5!$W$1:$AH$1=Q$2,TARGET_TR5!$W$2:$AH$2040)))))} -> 380080543086 | R39: {=_xlfn.VSTACK(_xlfn._xlws.FILTER(RSMES!Q3:AB1000,RSMES!A3:A1000<>""),_xlfn._xlws.FILTER(RLEGS!Q3:AB1030,RLEGS!A3:A1030<>""),_xlfn._xlws.FILTER(RSO!Q3:AB1000,RSO!A3:A1000<>""),_xlfn._xlws.FILTER(BPPLP!Q3:AB1000,BPPLP!A3:A1000<>""),_xlfn._xlws.FILTER(SSGS!Q3:AB1000,SSGS!A3:A1000<>""),_xlfn._xlws.FILTER(DIGIPRO!Q3:AB994,DIGIPRO!A3:A994<>""))} -> 31241561207 | S39: 62475423501 | T39: 97204977653 | U39: 130036808380 | V39: 163763871435 | W39: 163763871435 | X39: 163763871435 | Y39: 163763871435 | Z39: 163763871435 | AA39: 163763871435 | AB39: 163763871435 | AC39: 163763871435 | AD39: {=SUM(IF(TARGET_TR5!$B$2:$B$2040=$A39,IF(TARGET_TR5!$C$2:$C$2040=$C39,IF(TARGET_TR5!$E$2:$E$2040=$E39,IF(TARGET_TR5!$F$1:$Q$1=AD$2,TARGET_TR5!$F$2:$Q$2040)))))} -> 29765979369 | AE39: {=SUM(IF(TARGET_TR5!$B$2:$B$2040=$A39,IF(TARGET_TR5!$C$2:$C$2040=$C39,IF(TARGET_TR5!$E$2:$E$2040=$E39,IF(TARGET_TR5!$F$1:$Q$1=AE$2,TARGET_TR5!$F$2:$Q$2040)))))} -> 3.0111538e+10 | AF39: {=SUM(IF(TARGET_TR5!$B$2:$B$2040=$A39,IF(TARGET_TR5!$C$2:$C$2040=$C39,IF(TARGET_TR5!$E$2:$E$2040=$E39,IF(TARGET_TR5!$F$1:$Q$1=AF$2,TARGET_TR5!$F$2:$Q$2040)))))} -> 30276494268 | AG39: {=SUM(IF(TARGET_TR5!$B$2:$B$2040=$A39,IF(TARGET_TR5!$C$2:$C$2040=$C39,IF(TARGET_TR5!$E$2:$E$2040=$E39,IF(TARGET_TR5!$F$1:$Q$1=AG$2,TARGET_TR5!$F$2:$Q$2040)))))} -> 3.0724835e+10 | AH39: {=SUM(IF(TARGET_TR5!$B$2:$B$2040=$A39,IF(TARGET_TR5!$C$2:$C$2040=$C39,IF(TARGET_TR5!$E$2:$E$2040=$E39,IF(TARGET_TR5!$F$1:$Q$1=AH$2,TARGET_TR5!$F$2:$Q$2040)))))} -> 3.1055263e+10 | AI39: {=SUM(IF(TARGET_TR5!$B$2:$B$2040=$A39,IF(TARGET_TR5!$C$2:$C$2040=$C39,IF(TARGET_TR5!$E$2:$E$2040=$E39,IF(TARGET_TR5!$F$1:$Q$1=AI$2,TARGET_TR5!$F$2:$Q$2040)))))} -> 31056863100 | AJ39: {=SUM(IF(TARGET_TR5!$B$2:$B$2040=$A39,IF(TARGET_TR5!$C$2:$C$2040=$C39,IF(TARGET_TR5!$E$2:$E$2040=$E39,IF(TARGET_TR5!$F$1:$Q$1=AJ$2,TARGET_TR5!$F$2:$Q$2040)))))} -> 31802132087 | AK39: {=SUM(IF(TARGET_TR5!$B$2:$B$2040=$A39,IF(TARGET_TR5!$C$2:$C$2040=$C39,IF(TARGET_TR5!$E$2:$E$2040=$E39,IF(TARGET_TR5!$F$1:$Q$1=AK$2,TARGET_TR5!$F$2:$Q$2040)))))} -> 32281513125 | ... AO39: {=SUM(IF(TARGET_TR5!$B$2:$B$2040=$A39,IF(TARGET_TR5!$C$2:$C$2040=$C39,IF(TARGET_TR5!$E$2:$E$2040=$E39,IF(TARGET_TR5!$F$1:$Q$1=AO$2,TARGET_TR5!$F$2:$Q$2040)))))} -> 33791231264 | AP39: {=_xlfn.VSTACK(_xlfn._xlws.FILTER(RSMES!AO3:AZ1000,RSMES!A3:A1000<>""),_xlfn._xlws.FILTER(RLEGS!AO3:AZ1030,RLEGS!A3:A1030<>""),_xlfn._xlws.FILTER(RSO!AO3:AZ1000,RSO!A3:A1000<>""),_xlfn._xlws.FILTER(BPPLP!AO3:AZ1000,BPPLP!A3:A1000<>""),_xlfn._xlws.FILTER(SSGS!AO3:AZ1000,SSGS!A3:A1000<>""),_xlfn._xlws.FILTER(DIGIPRO!AO3:AZ994,DIGIPRO!A3:A994<>""))} -> 31241561207 | AQ39: 31233862294 | AR39: 34729554152 | AS39: 32831830727 | AT39: 33727063055 | AU39: 0 | AV39: 0 | AW39: 0 | AX39: 0 | AY39: 0 | AZ39: 0 | BA39: 0 | BB39: =IF(F39=0,1,(R39/F39)) -> 1.0495728 | BC39: =IF(G39=0,1,(S39/G39)) -> 1.043387 | BD39: =IF(H39=0,1,(T39/H39)) -> 1.0782102 | BE39: =IF(I39=0,1,(U39/I39)) -> 1.0757615 | BF39: =IF(J39=0,1,(V39/J39)) -> 1.0778611 | BG39: =IF(K39=0,1,(W39/K39)) -> 0.89492869 | BH39: =IF(L39=0,1,(X39/L39)) -> 0.76242611 | BI39: =IF(M39=0,1,(Y39/M39)) -> 0.66281139 | ... BM39: =IF(Q39=0,1,(AC39/Q39)) -> 0.43086623
A40: RKAP | B40: SMES | C40: Revenue SMES | D40: Rp M | E40: PAPUA | F40: {=SUM(IF(TARGET_TR5!$B$2:$B$2040=$A40,IF(TARGET_TR5!$C$2:$C$2040=$C40,IF(TARGET_TR5!$E$2:$E$2040=$E40,IF(TARGET_TR5!$W$1:$AH$1=F$2,TARGET_TR5!$W$2:$AH$2040)))))} -> 2.5907798e+09 | G40: {=SUM(IF(TARGET_TR5!$B$2:$B$2040=$A40,IF(TARGET_TR5!$C$2:$C$2040=$C40,IF(TARGET_TR5!$E$2:$E$2040=$E40,IF(TARGET_TR5!$W$1:$AH$1=G$2,TARGET_TR5!$W$2:$AH$2040)))))} -> 5.2116364e+09 | H40: {=SUM(IF(TARGET_TR5!$B$2:$B$2040=$A40,IF(TARGET_TR5!$C$2:$C$2040=$C40,IF(TARGET_TR5!$E$2:$E$2040=$E40,IF(TARGET_TR5!$W$1:$AH$1=H$2,TARGET_TR5!$W$2:$AH$2040)))))} -> 7.8468506e+09 | I40: {=SUM(IF(TARGET_TR5!$B$2:$B$2040=$A40,IF(TARGET_TR5!$C$2:$C$2040=$C40,IF(TARGET_TR5!$E$2:$E$2040=$E40,IF(TARGET_TR5!$W$1:$AH$1=I$2,TARGET_TR5!$W$2:$AH$2040)))))} -> 1.0521088e+10 | J40: {=SUM(IF(TARGET_TR5!$B$2:$B$2040=$A40,IF(TARGET_TR5!$C$2:$C$2040=$C40,IF(TARGET_TR5!$E$2:$E$2040=$E40,IF(TARGET_TR5!$W$1:$AH$1=J$2,TARGET_TR5!$W$2:$AH$2040)))))} -> 1.3224084e+10 | K40: {=SUM(IF(TARGET_TR5!$B$2:$B$2040=$A40,IF(TARGET_TR5!$C$2:$C$2040=$C40,IF(TARGET_TR5!$E$2:$E$2040=$E40,IF(TARGET_TR5!$W$1:$AH$1=K$2,TARGET_TR5!$W$2:$AH$2040)))))} -> 1.5927221e+10 | L40: {=SUM(IF(TARGET_TR5!$B$2:$B$2040=$A40,IF(TARGET_TR5!$C$2:$C$2040=$C40,IF(TARGET_TR5!$E$2:$E$2040=$E40,IF(TARGET_TR5!$W$1:$AH$1=L$2,TARGET_TR5!$W$2:$AH$2040)))))} -> 1.8695224e+10 | M40: {=SUM(IF(TARGET_TR5!$B$2:$B$2040=$A40,IF(TARGET_TR5!$C$2:$C$2040=$C40,IF(TARGET_TR5!$E$2:$E$2040=$E40,IF(TARGET_TR5!$W$1:$AH$1=M$2,TARGET_TR5!$W$2:$AH$2040)))))} -> 2.1504951e+10 | ... Q40: {=SUM(IF(TARGET_TR5!$B$2:$B$2040=$A40,IF(TARGET_TR5!$C$2:$C$2040=$C40,IF(TARGET_TR5!$E$2:$E$2040=$E40,IF(TARGET_TR5!$W$1:$AH$1=Q$2,TARGET_TR5!$W$2:$AH$2040)))))} -> 3.3081559e+10 | R40: 2772904753 | S40: 5550980939 | T40: 8477291509 | U40: 11357597038 | V40: 14197168965 | W40: 14197168965 | X40: 14197168965 | Y40: 14197168965 | Z40: 14197168965 | AA40: 14197168965 | AB40: 14197168965 | AC40: 14197168965 | AD40: {=SUM(IF(TARGET_TR5!$B$2:$B$2040=$A40,IF(TARGET_TR5!$C$2:$C$2040=$C40,IF(TARGET_TR5!$E$2:$E$2040=$E40,IF(TARGET_TR5!$F$1:$Q$1=AD$2,TARGET_TR5!$F$2:$Q$2040)))))} -> 2.5907798e+09 | AE40: {=SUM(IF(TARGET_TR5!$B$2:$B$2040=$A40,IF(TARGET_TR5!$C$2:$C$2040=$C40,IF(TARGET_TR5!$E$2:$E$2040=$E40,IF(TARGET_TR5!$F$1:$Q$1=AE$2,TARGET_TR5!$F$2:$Q$2040)))))} -> 2.6208566e+09 | AF40: {=SUM(IF(TARGET_TR5!$B$2:$B$2040=$A40,IF(TARGET_TR5!$C$2:$C$2040=$C40,IF(TARGET_TR5!$E$2:$E$2040=$E40,IF(TARGET_TR5!$F$1:$Q$1=AF$2,TARGET_TR5!$F$2:$Q$2040)))))} -> 2.6352142e+09 | AG40: {=SUM(IF(TARGET_TR5!$B$2:$B$2040=$A40,IF(TARGET_TR5!$C$2:$C$2040=$C40,IF(TARGET_TR5!$E$2:$E$2040=$E40,IF(TARGET_TR5!$F$1:$Q$1=AG$2,TARGET_TR5!$F$2:$Q$2040)))))} -> 2.674237e+09 | AH40: {=SUM(IF(TARGET_TR5!$B$2:$B$2040=$A40,IF(TARGET_TR5!$C$2:$C$2040=$C40,IF(TARGET_TR5!$E$2:$E$2040=$E40,IF(TARGET_TR5!$F$1:$Q$1=AH$2,TARGET_TR5!$F$2:$Q$2040)))))} -> 2.7029969e+09 | AI40: {=SUM(IF(TARGET_TR5!$B$2:$B$2040=$A40,IF(TARGET_TR5!$C$2:$C$2040=$C40,IF(TARGET_TR5!$E$2:$E$2040=$E40,IF(TARGET_TR5!$F$1:$Q$1=AI$2,TARGET_TR5!$F$2:$Q$2040)))))} -> 2.7031361e+09 | AJ40: {=SUM(IF(TARGET_TR5!$B$2:$B$2040=$A40,IF(TARGET_TR5!$C$2:$C$2040=$C40,IF(TARGET_TR5!$E$2:$E$2040=$E40,IF(TARGET_TR5!$F$1:$Q$1=AJ$2,TARGET_TR5!$F$2:$Q$2040)))))} -> 2.7680031e+09 | AK40: {=SUM(IF(TARGET_TR5!$B$2:$B$2040=$A40,IF(TARGET_TR5!$C$2:$C$2040=$C40,IF(TARGET_TR5!$E$2:$E$2040=$E40,IF(TARGET_TR5!$F$1:$Q$1=AK$2,TARGET_TR5!$F$2:$Q$2040)))))} -> 2.8097276e+09 | ... AO40: {=SUM(IF(TARGET_TR5!$B$2:$B$2040=$A40,IF(TARGET_TR5!$C$2:$C$2040=$C40,IF(TARGET_TR5!$E$2:$E$2040=$E40,IF(TARGET_TR5!$F$1:$Q$1=AO$2,TARGET_TR5!$F$2:$Q$2040)))))} -> 2.9411308e+09 | AP40: 2772904753 | AQ40: 2778076186 | AR40: 2926310570 | AS40: 2880305529 | AT40: 2839571927 | AU40: 0 | AV40: 0 | AW40: 0 | AX40: 0 | AY40: 0 | AZ40: 0 | BA40: 0 | BB40: =IF(F40=0,1,(R40/F40)) -> 1.0702973 | BC40: =IF(G40=0,1,(S40/G40)) -> 1.0651128 | BD40: =IF(H40=0,1,(T40/H40)) -> 1.0803432 | BE40: =IF(I40=0,1,(U40/I40)) -> 1.0795079 | BF40: =IF(J40=0,1,(V40/J40)) -> 1.0735843 | BG40: =IF(K40=0,1,(W40/K40)) -> 0.89137768 | BH40: =IF(L40=0,1,(X40/L40)) -> 0.75940086 | BI40: =IF(M40=0,1,(Y40/M40)) -> 0.66018141 | ... BM40: =IF(Q40=0,1,(AC40/Q40)) -> 0.42915659
